Workbook
Name ActivityNames: hiddenData!$A$1:$A$18
Name Bottleneck0: hiddenData!$H$1:$H$18
Name Bottleneck1: hiddenData!$I$1:$I$18
Name Consumption0: hiddenData!$F$1:$F$4
Name Consumption1: hiddenData!$G$1:$G$4
Name Resources: hiddenData!$F$5:$F$8
Name TotalCosts0: hiddenData!$B$1:$B$18
Name TotalCosts1: hiddenData!$C$1:$C$18
Name TotalTime0: hiddenData!$D$1:$D$18
Name TotalTime1: hiddenData!$E$1:$E$18

Sheet Overview
A1: Report | B1: Simulation
A2: Date | B2: 4/20/26
A3: Time | B3: 11:12 PM
A4: User | B4: Mohamed Jaafar
A5: Process | B5: ACME Portfolio Allocator — ML Application Development Workflow
A7: Used scenario | B7: Duration in days | C7: Total cycle time | D7: Resource consumption | E7: Bottlenecks
A8: mvpp | B8: 5 | C8: 0 | D8: 2.8333333 | E8: MLOps / Deployment; Model Development
A9: mvp | B9: 5 | C9: 0 | D9: 4.2625 | E9: Model Development; MLOps / Deployment; Monitoring & Retraining; Data Engineering

Sheet Costs
A1: Report | B1: Simulation
A2: Date | B2: 4/20/26
A3: Time | B3: 11:12 PM
A4: User | B4: Mohamed Jaafar
A5: Process | B5: ACME Portfolio Allocator — ML Application Development Workflow
A7: Execution costs of a process instance are the sum of fixed activity costs and resources costs. The latter ones are computed using defined responsibilities and activity execution durations. The following table shows selected process instance costs as well as the total sum of all costs:
A10: Used scenario | B10: Duration in days | C10: Average | D10: Minimum | E10: Maximum | F10: Total costs
A11: mvpp | B11: 5 | C11: 0 | D11: 0 | E11: 0 | F11: 152200
A12: mvp | B12: 5 | C12: 0 | D12: 0 | E12: 0 | F12: 317285
A14: The following table shows the costs caused by every activity of your process:
A16: Task | B16: Used scenario | C16: Duration in days | D16: Completed instances | E16: Average | F16: Minimum | G16: Maximum | H16: Total costs
A17: Ingest yfinance Prices (12 ETFs) | B17: mvpp | C17: 5 | D17: 20 | E17: 203.33 | F17: 203.33 | G17: 203.33 | H17: 4066.67
B18: mvp | C18: 5 | D18: 31 | E18: 203.33 | F18: 203.33 | G18: 203.33 | H18: 6303.33
A19: Generate Synthetic Client Profiles (N=2500) | B19: mvpp | C19: 5 | D19: 20 | E19: 101.67 | F19: 101.67 | G19: 101.67 | H19: 2033.33
B20: mvp | C20: 5 | D20: 31 | E20: 101.67 | F20: 101.67 | G20: 101.67 | H20: 3151.67
A21: Apply Adviser Labelling Rule | B21: mvpp | C21: 5 | D21: 20 | E21: 152.5 | F21: 152.5 | G21: 152.5 | H21: 3050
B22: mvp | C22: 5 | D22: 31 | E22: 152.5 | F22: 152.5 | G22: 152.5 | H22: 4727.5
A23: Build Feature Matrix (7 client + 3 market) | B23: mvpp | C23: 5 | D23: 20 | E23: 508.33 | F23: 508.33 | G23: 508.33 | H23: 10166.67
B24: mvp | C24: 5 | D24: 31 | E24: 508.33 | F24: 508.33 | G24: 508.33 | H24: 15758.33
A25: Train/Test Split + StandardScaler | B25: mvpp | C25: 5 | D25: 20 | E25: 50.83 | F25: 50.83 | G25: 50.83 | H25: 1016.67
B26: mvp | C26: 5 | D26: 31 | E26: 50.83 | F26: 50.83 | G26: 50.83 | H26: 1575.83
A27: Train DecisionTreeClassifier | B27: mvpp | C27: 5 | D27: 20 | E27: 101.67 | F27: 101.67 | G27: 101.67 | H27: 2033.33
B28: mvp | C28: 5 | D28: 31 | E28: 101.67 | F28: 101.67 | G28: 101.67 | H28: 3151.67
A29: Train MLPClassifier | B29: mvpp | C29: 5 | D29: 20 | E29: 403.33 | F29: 403.33 | G29: 403.33 | H29: 8066.67
B30: mvp | C30: 5 | D30: 31 | E30: 403.33 | F30: 403.33 | G30: 403.33 | H30: 12503.33
A31: Compare Accuracy / F1 / ROC-AUC | B31: mvpp | C31: 5 | D31: 74 | E31: 505 | F31: 505 | G31: 505 | H31: 37370
B32: mvp | C32: 5 | D32: 145 | E32: 505 | F32: 505 | G32: 505 | H32: 73725
A33: Select Random Forest (best accuracy + explainable) | B33: mvpp | C33: 5 | D33: 60 | E33: 300.83 | F33: 300.83 | G33: 300.83 | H33: 18050
B34: mvp | C34: 5 | D34: 54 | E34: 300.83 | F34: 300.83 | G34: 300.83 | H34: 16245
A35: Compute SHAP for Transparency | B35: mvpp | C35: 5 | D35: 60 | E35: 56.67 | F35: 56.67 | G35: 56.67 | H35: 3400
B36: mvp | C36: 5 | D36: 54 | E36: 56.67 | F36: 56.67 | G36: 56.67 | H36: 3060
A37: joblib.dump Model + Scaler + Metadata | B37: mvpp | C37: 5 | D37: 60 | E37: 400.83 | F37: 400.83 | G37: 400.83 | H37: 24050
B38: mvp | C38: 5 | D38: 54 | E38: 400.83 | F38: 400.83 | G38: 400.83 | H38: 21645
A39: Register in Model Registry | B39: mvpp | C39: 5 | D39: 60 | E39: 52.5 | F39: 52.5 | G39: 52.5 | H39: 3150
B40: mvp | C40: 5 | D40: 54 | E40: 52.5 | F40: 52.5 | G40: 52.5 | H40: 2835
A41: Integration Test (load + predict new case) | B41: mvpp | C41: 5 | D41: 43 | E41: 190 | F41: 190 | G41: 190 | H41: 8320
B42: mvp | C42: 5 | D42: 39 | E42: 190 | F42: 190 | G42: 190 | H42: 7560
A43: Serve via Streamlit Adviser UI | B43: mvpp | C43: 5 | D43: 0 | E43: 0 | F43: 0 | G43: 0 | H43: 0
B44: mvp | C44: 5 | D44: 17 | E44: 505 | F44: 505 | G44: 505 | H44: 8585
A45: Log Predictions + Probabilities | B45: mvpp | C45: 5 | D45: 0 | E45: 0 | F45: 0 | G45: 0 | H45: 0
...

Sheet Total cost charts
A1: Report | B1: Simulation
A2: Date | B2: 4/20/26
A3: Time | B3: 11:12 PM
A4: User | B4: Mohamed Jaafar
A5: Process | B5: ACME Portfolio Allocator — ML Application Development Workflow

Sheet Total cycle time
A1: Report | B1: Simulation
A2: Date | B2: 4/20/26
A3: Time | B3: 11:12 PM
A4: User | B4: Mohamed Jaafar
A5: Process | B5: ACME Portfolio Allocator — ML Application Development Workflow
A8: The cycle time of a process instance is measured between its start and completion. The following table shows selected process instance cycle times as well as the total sum of all run cycles:
A10: Used scenario | B10: Duration in days | C10: Average | D10: Minimum | E10: Maximum | F10: Total cycle time
A11: mvpp | B11: 5 | C11: 0 | D11: 0 | E11: 0 | F11: 0
A12: mvp | B12: 5 | C12: 0 | D12: 0 | E12: 0 | F12: 0
A15: Execution times incl. waiting times
A16: The following table shows for each activity how long its execution took with respect to existing working schedules without taking available resources into account:
A18: Task | B18: Used scenario | C18: Duration in days | D18: Completed instances | E18: Average | F18: Minimum | G18: Maximum | H18: Total execution time
A19: Ingest yfinance Prices (12 ETFs) | B19: mvpp | C19: 5 | D19: 20 | E19: 0.0027777778 | F19: 0.0027777778 | G19: 0.0027777778 | H19: 0.055555556
B20: mvp | C20: 5 | D20: 31 | E20: 0.0027777778 | F20: 0.0027777778 | G20: 0.0027777778 | H20: 0.086111111
A21: Generate Synthetic Client Profiles (N=2500) | B21: mvpp | C21: 5 | D21: 20 | E21: 0.0013888889 | F21: 0.0013888889 | G21: 0.0013888889 | H21: 0.027777778
B22: mvp | C22: 5 | D22: 31 | E22: 0.0013888889 | F22: 0.0013888889 | G22: 0.0013888889 | H22: 0.043055556
A23: Apply Adviser Labelling Rule | B23: mvpp | C23: 5 | D23: 20 | E23: 0.0020833333 | F23: 0.0020833333 | G23: 0.0020833333 | H23: 0.041666667
B24: mvp | C24: 5 | D24: 31 | E24: 0.0020833333 | F24: 0.0020833333 | G24: 0.0020833333 | H24: 0.064583333
A25: Build Feature Matrix (7 client + 3 market) | B25: mvpp | C25: 5 | D25: 20 | E25: 0.0069444444 | F25: 0.0069444444 | G25: 0.0069444444 | H25: 0.13888889
B26: mvp | C26: 5 | D26: 31 | E26: 0.0069444444 | F26: 0.0069444444 | G26: 0.0069444444 | H26: 0.21527778
A27: Train/Test Split + StandardScaler | B27: mvpp | C27: 5 | D27: 20 | E27: 0.00069444444 | F27: 0.00069444444 | G27: 0.00069444444 | H27: 0.013888889
B28: mvp | C28: 5 | D28: 31 | E28: 0.00069444444 | F28: 0.00069444444 | G28: 0.00069444444 | H28: 0.021527778
A29: Train DecisionTreeClassifier | B29: mvpp | C29: 5 | D29: 20 | E29: 0.0013888889 | F29: 0.0013888889 | G29: 0.0013888889 | H29: 0.027777778
B30: mvp | C30: 5 | D30: 31 | E30: 0.0013888889 | F30: 0.0013888889 | G30: 0.0013888889 | H30: 0.043055556
A31: Train MLPClassifier | B31: mvpp | C31: 5 | D31: 20 | E31: 0.0027777778 | F31: 0.0027777778 | G31: 0.0027777778 | H31: 0.055555556
B32: mvp | C32: 5 | D32: 31 | E32: 0.0027777778 | F32: 0.0027777778 | G32: 0.0027777778 | H32: 0.086111111
A33: Compare Accuracy / F1 / ROC-AUC | B33: mvpp | C33: 5 | D33: 74 | E33: 0.0041666667 | F33: 0.0041666667 | G33: 0.0041666667 | H33: 0.30833333
B34: mvp | C34: 5 | D34: 145 | E34: 0.013356481 | F34: 0.0041666667 | G34: 0.67083333 | H34: 1.9520833
A35: Select Random Forest (best accuracy + explainable) | B35: mvpp | C35: 5 | D35: 60 | E35: 0.00069444444 | F35: 0.00069444444 | G35: 0.00069444444 | H35: 0.041666667
B36: mvp | C36: 5 | D36: 54 | E36: 0.00069444444 | F36: 0.00069444444 | G36: 0.00069444444 | H36: 0.0375
A37: Compute SHAP for Transparency | B37: mvpp | C37: 5 | D37: 60 | E37: 0.016666667 | F37: 0.0055555556 | G37: 0.67222222 | H37: 1
B38: mvp | C38: 5 | D38: 54 | E38: 0.017893519 | F38: 0.0055555556 | G38: 0.67222222 | H38: 0.96666667
A39: joblib.dump Model + Scaler + Metadata | B39: mvpp | C39: 5 | D39: 60 | E39: 0.00069444444 | F39: 0.00069444444 | G39: 0.00069444444 | H39: 0.041666667
B40: mvp | C40: 5 | D40: 54 | E40: 0.00069444444 | F40: 0.00069444444 | G40: 0.00069444444 | H40: 0.0375
A41: Register in Model Registry | B41: mvpp | C41: 5 | D41: 60 | E41: 0.0020833333 | F41: 0.0020833333 | G41: 0.0020833333 | H41: 0.125
B42: mvp | C42: 5 | D42: 54 | E42: 0.0020833333 | F42: 0.0020833333 | G42: 0.0020833333 | H42: 0.1125
A43: Integration Test (load + predict new case) | B43: mvpp | C43: 5 | D43: 43 | E43: 0.095347222 | F43: 0.033333333 | G43: 0.7 | H43: 4.1333333
B44: mvp | C44: 5 | D44: 39 | E44: 0.084606481 | F44: 0.033333333 | G44: 0.7 | H44: 3.3333333
A45: Serve via Streamlit Adviser UI | B45: mvpp | C45: 5 | D45: 0 | E45: 0 | F45: 0 | G45: 0 | H45: 0
B46: mvp | C46: 5 | D46: 17 | E46: 0.0041666667 | F46: 0.0041666667 | G46: 0.0041666667 | H46: 0.070833333
...

Sheet Total time charts
A1: Report | B1: Simulation
A2: Date | B2: 4/20/26
A3: Time | B3: 11:12 PM
A4: User | B4: Mohamed Jaafar
A5: Process | B5: ACME Portfolio Allocator — ML Application Development Workflow

Sheet Resource consumption
A1: Report | B1: Simulation
A2: Date | B2: 4/20/26
A3: Time | B3: 11:12 PM
A4: User | B4: Mohamed Jaafar
A5: Process | B5: ACME Portfolio Allocator — ML Application Development Workflow
A7: The execution of activities is performed by resources. The following table shows the workload of all resources in your scenario:
A10: Resources | B10: Used scenario | C10: Duration in days | D10: Consumed time | E10: Workload
A11: MLOps / Deployment | B11: mvpp | C11: 5 | D11: 1.6333333 | E11: 0.98
B12: mvp | C12: 5 | D12: 1.5541667 | E12: 0.9325
A13: Model Development | B13: mvpp | C13: 5 | D13: 0.96944444 | E13: 0.5817
B14: mvp | C14: 5 | D14: 1.6298611 | E14: 0.9779
A15: Data Engineering | B15: mvpp | C15: 5 | D15: 0.26388889 | E15: 0.1583
B16: mvp | C16: 5 | D16: 0.40902778 | E16: 0.2454
A17: Monitoring & Retraining | B17: mvpp | C17: 5 | D17: 0 | E17: 0
B18: mvp | C18: 5 | D18: 0.70694444 | E18: 0.4242
A20: Legend
A21: All values are relative to the highest value
A22: Latest run | B22: Previous run
A23: 100% | B23: 100%
A24: >87.5% | B24: >87.5%
A25: >75% | B25: >75%
A26: >62.5% | B26: >62.5%
A27: >50% | B27: >50%
A28: <=50% or smallest value | B28: <=50% or smallest value

Sheet Resource consumption charts
A1: Report | B1: Simulation
A2: Date | B2: 4/20/26
A3: Time | B3: 11:12 PM
A4: User | B4: Mohamed Jaafar
A5: Process | B5: ACME Portfolio Allocator — ML Application Development Workflow

Sheet Bottlenecks
A1: Report | B1: Simulation
A2: Date | B2: 4/20/26
A3: Time | B3: 11:12 PM
A4: User | B4: Mohamed Jaafar
A5: Process | B5: ACME Portfolio Allocator — ML Application Development Workflow
A7: The execution of a process instance might be delayed due to a shortage of resources: When an activity is ready for execution but all resources are already allocated, the execution has to wait. The following table shows activities that were delayed:
A10: Resources | B10: Task | C10: Used scenario | D10: Duration in days | E10: Total waiting time | F10: Instances waiting at termination
A11: MLOps / Deployment | B11: Integration Test (load + predict new case) | C11: mvpp | D11: 5 | E11: 31.245139 | F11: 16
C12: mvp | D12: 5 | E12: 40.513194 | F12: 14
B13: joblib.dump Model + Scaler + Metadata | C13: mvpp | D13: 5 | E13: 2.9548611 | F13: 0
C14: mvp | D14: 5 | E14: 2.1145833 | F14: 0
B15: Register in Model Registry | C15: mvpp | D15: 5 | E15: 0.97777778 | F15: 0
C16: mvp | D16: 5 | E16: 1.0888889 | F16: 0
B17: Serve via Streamlit Adviser UI | C17: mvpp | D17: 5 | E17: 89.835417 | F17: 43
C18: mvp | D18: 5 | E18: 27.642361 | F18: 22
A19: Monitoring & Retraining | B19: Trigger Retraining | C19: mvpp | D19: 5 | E19: 0 | F19: 0
C20: mvp | D20: 5 | E20: 2.5 | F20: 0
B21: Check Class-Mix + Confidence Drift | C21: mvpp | D21: 5 | E21: 0 | F21: 0
C22: mvp | D22: 5 | E22: 7.4861111 | F22: 0
B23: Log Predictions + Probabilities | C23: mvpp | D23: 5 | E23: 0 | F23: 0
C24: mvp | D24: 5 | E24: 1.35 | F24: 0
A25: Data Engineering | B25: Build Feature Matrix (7 client + 3 market) | C25: mvpp | D25: 5 | E25: 0 | F25: 0
C26: mvp | D26: 5 | E26: 0.18819444 | F26: 0
B27: Generate Synthetic Client Profiles (N=2500) | C27: mvpp | D27: 5 | E27: 0 | F27: 0
C28: mvp | D28: 5 | E28: 0.034722222 | F28: 0
B29: Apply Adviser Labelling Rule | C29: mvpp | D29: 5 | E29: 0 | F29: 0
C30: mvp | D30: 5 | E30: 0.048611111 | F30: 0
B31: Ingest yfinance Prices (12 ETFs) | C31: mvpp | D31: 5 | E31: 0 | F31: 0
C32: mvp | D32: 5 | E32: 0.020138889 | F32: 0
A33: Model Development | B33: Compute SHAP for Transparency | C33: mvpp | D33: 5 | E33: 1.0826389 | F33: 0
C34: mvp | D34: 5 | E34: 15.011111 | F34: 0
B35: Compare Accuracy / F1 / ROC-AUC | C35: mvpp | D35: 5 | E35: 0.45277778 | F35: 0
C36: mvp | D36: 5 | E36: 26.839583 | F36: 12
B37: Train MLPClassifier | C37: mvpp | D37: 5 | E37: 0.13888889 | F37: 0
C38: mvp | D38: 5 | E38: 0.51180556 | F38: 0
B39: Train DecisionTreeClassifier | C39: mvpp | D39: 5 | E39: 0.11111111 | F39: 0
C40: mvp | D40: 5 | E40: 0.14791667 | F40: 0
B41: Select Random Forest (best accuracy + explainable) | C41: mvpp | D41: 5 | E41: 0.40347222 | F41: 0
C42: mvp | D42: 5 | E42: 21.639583 | F42: 25
B43: Train RandomForestClassifier | C43: mvpp | D43: 5 | E43: 0.042361111 | F43: 0
...

Sheet Bottleneck charts
A1: Report | B1: Simulation
A2: Date | B2: 4/20/26
A3: Time | B3: 11:12 PM
A4: User | B4: Mohamed Jaafar
A5: Process | B5: ACME Portfolio Allocator — ML Application Development Workflow

Sheet hiddenData
A1: =Costs!A17 | B1: =Costs!H17 | C1: =Costs!H18 | D1: ='Total cycle time'!H62 | E1: ='Total cycle time'!H63 | F1: ='Resource consumption'!D11 | G1: ='Resource consumption'!D12 | H1: =Bottlenecks!E11 | I1: ='Bottlenecks'!E12 | J1: Latest run Total costs
A2: =Costs!A19 | B2: =Costs!H19 | C2: =Costs!H20 | D2: ='Total cycle time'!H64 | E2: ='Total cycle time'!H65 | F2: ='Resource consumption'!D13 | G2: ='Resource consumption'!D14 | H2: =Bottlenecks!E13 | I2: ='Bottlenecks'!E13 | J2: Previous run Total costs
A3: =Costs!A21 | B3: =Costs!H21 | C3: =Costs!H22 | D3: ='Total cycle time'!H66 | E3: ='Total cycle time'!H67 | F3: ='Resource consumption'!D15 | G3: ='Resource consumption'!D16 | H3: =Bottlenecks!E15 | I3: ='Bottlenecks'!E14 | J3: Latest run Total cycle time
A4: =Costs!A23 | B4: =Costs!H23 | C4: =Costs!H24 | D4: ='Total cycle time'!H68 | E4: ='Total cycle time'!H69 | F4: ='Resource consumption'!D17 | G4: ='Resource consumption'!D18 | H4: =Bottlenecks!E17 | I4: ='Bottlenecks'!E15 | J4: Previous run Total cycle time
A5: =Costs!A25 | B5: =Costs!H25 | C5: =Costs!H26 | D5: ='Total cycle time'!H70 | E5: ='Total cycle time'!H71 | F5: ='Resource consumption'!A11 | H5: =Bottlenecks!E19 | I5: ='Bottlenecks'!E16 | J5: Latest run Workload
A6: =Costs!A27 | B6: =Costs!H27 | C6: =Costs!H28 | D6: ='Total cycle time'!H72 | E6: ='Total cycle time'!H73 | F6: ='Resource consumption'!A13 | H6: =Bottlenecks!E21 | I6: ='Bottlenecks'!E17 | J6: Previous run Workload
A7: =Costs!A29 | B7: =Costs!H29 | C7: =Costs!H30 | D7: ='Total cycle time'!H74 | E7: ='Total cycle time'!H75 | F7: ='Resource consumption'!A15 | H7: =Bottlenecks!E23 | I7: ='Bottlenecks'!E18 | J7: Latest run Total waiting time
A8: =Costs!A31 | B8: =Costs!H31 | C8: =Costs!H32 | D8: ='Total cycle time'!H76 | E8: ='Total cycle time'!H77 | F8: ='Resource consumption'!A17 | H8: =Bottlenecks!E25 | I8: ='Bottlenecks'!E19 | J8: Previous run Total waiting time
A9: =Costs!A33 | B9: =Costs!H33 | C9: =Costs!H34 | D9: ='Total cycle time'!H78 | E9: ='Total cycle time'!H79 | H9: =Bottlenecks!E27 | I9: ='Bottlenecks'!E20
A10: =Costs!A35 | B10: =Costs!H35 | C10: =Costs!H36 | D10: ='Total cycle time'!H80 | E10: ='Total cycle time'!H81 | H10: =Bottlenecks!E29 | I10: ='Bottlenecks'!E21
A11: =Costs!A37 | B11: =Costs!H37 | C11: =Costs!H38 | D11: ='Total cycle time'!H82 | E11: ='Total cycle time'!H83 | H11: =Bottlenecks!E31 | I11: ='Bottlenecks'!E22
A12: =Costs!A39 | B12: =Costs!H39 | C12: =Costs!H40 | D12: ='Total cycle time'!H84 | E12: ='Total cycle time'!H85 | H12: =Bottlenecks!E33 | I12: ='Bottlenecks'!E23
A13: =Costs!A41 | B13: =Costs!H41 | C13: =Costs!H42 | D13: ='Total cycle time'!H86 | E13: ='Total cycle time'!H87 | H13: =Bottlenecks!E35 | I13: ='Bottlenecks'!E24
A14: =Costs!A43 | B14: =Costs!H43 | C14: =Costs!H44 | D14: ='Total cycle time'!H88 | E14: ='Total cycle time'!H89 | H14: =Bottlenecks!E37 | I14: ='Bottlenecks'!E25
A15: =Costs!A45 | B15: =Costs!H45 | C15: =Costs!H46 | D15: ='Total cycle time'!H90 | E15: ='Total cycle time'!H91 | H15: =Bottlenecks!E39 | I15: ='Bottlenecks'!E26
A16: =Costs!A47 | B16: =Costs!H47 | C16: =Costs!H48 | D16: ='Total cycle time'!H92 | E16: ='Total cycle time'!H93 | H16: =Bottlenecks!E41 | I16: ='Bottlenecks'!E27
A17: =Costs!A49 | B17: =Costs!H49 | C17: =Costs!H50 | D17: ='Total cycle time'!H94 | E17: ='Total cycle time'!H95 | H17: =Bottlenecks!E43 | I17: ='Bottlenecks'!E28
A18: =Costs!A51 | B18: =Costs!H51 | C18: =Costs!H52 | D18: ='Total cycle time'!H96 | E18: ='Total cycle time'!H97 | H18: =Bottlenecks!E45 | I18: ='Bottlenecks'!E29

Sheet Scenario mvpp
A1: Report | B1: Simulation
A2: Date | B2: 4/20/26
A3: Time | B3: 11:12 PM
A4: User | B4: Mohamed Jaafar
A5: Process | B5: ACME Portfolio Allocator — ML Application Development Workflow
A7: Costs and Duration
A9: Task | B9: Execution costs | C9: Execution time
A10: Ingest yfinance Prices (12 ETFs) | B10: 200 | C10: 00h 04m
A11: Generate Synthetic Client Profiles (N=2500) | B11: 100 | C11: 00h 02m
A12: Apply Adviser Labelling Rule | B12: 150 | C12: 00h 03m
A13: Build Feature Matrix (7 client + 3 market) | B13: 500 | C13: 00h 10m
A14: Train/Test Split + StandardScaler | B14: 50 | C14: 00h 01m
A15: Train DecisionTreeClassifier | B15: 100 | C15: 00h 02m
A16: Train MLPClassifier | B16: 400 | C16: 00h 04m
A17: Compare Accuracy / F1 / ROC-AUC | B17: 500 | C17: 00h 06m
A18: Select Random Forest (best accuracy + explainable) | B18: 300 | C18: 00h 01m
A19: Compute SHAP for Transparency | B19: 50 | C19: 00h 08m
A20: joblib.dump Model + Scaler + Metadata | B20: 400 | C20: 00h 01m
A21: Register in Model Registry | B21: 50 | C21: 00h 03m
... A27: Train RandomForestClassifier | B27: 800 | C27: 00h 08m
A30: Frequency and probabilities
A32: Start event | B32: Frequency
A33: Build / Retrain Trigger | B33: On Mon-Fri; overall 20 times
A35: Gateway | B35: Decision | C35: Probability
A36: Meets deployment threshold? | B36: No (retune) | C36: 0.2
B37: Yes | C37: 0.8
A38: Drift detected? | B38: No | C38: 0.8
B39: Yes | C39: 0.2
A40: Retire model? | B40: No | C40: 0.97
B41: Yes | C41: 0.03
A44: Resources
A46: Role | B46: Work schedules | C46: Costs/hour
A47: Data Engineering | B47: 1 employees; 40 hours per week | C47: 50
A48: MLOps / Deployment | B48: 1 employees; 40 hours per week | C48: 50
A49: Model Development | B49: 1 employees; 40 hours per week | C49: 50
A50: Monitoring & Retraining | B50: 1 employees; 40 hours per week | C50: 50

Sheet Scenario mvp
A1: Report | B1: Simulation
A2: Date | B2: 4/20/26
A3: Time | B3: 11:12 PM
A4: User | B4: Mohamed Jaafar
A5: Process | B5: ACME Portfolio Allocator — ML Application Development Workflow
A7: Costs and Duration
A9: Task | B9: Execution costs | C9: Execution time
A10: Ingest yfinance Prices (12 ETFs) | B10: 200 | C10: 00h 04m
A11: Generate Synthetic Client Profiles (N=2500) | B11: 100 | C11: 00h 02m
A12: Apply Adviser Labelling Rule | B12: 150 | C12: 00h 03m
A13: Build Feature Matrix (7 client + 3 market) | B13: 500 | C13: 00h 10m
A14: Train/Test Split + StandardScaler | B14: 50 | C14: 00h 01m
A15: Train DecisionTreeClassifier | B15: 100 | C15: 00h 02m
A16: Train MLPClassifier | B16: 400 | C16: 00h 04m
A17: Compare Accuracy / F1 / ROC-AUC | B17: 500 | C17: 00h 06m
A18: Select Random Forest (best accuracy + explainable) | B18: 300 | C18: 00h 01m
A19: Compute SHAP for Transparency | B19: 50 | C19: 00h 08m
A20: joblib.dump Model + Scaler + Metadata | B20: 400 | C20: 00h 01m
A21: Register in Model Registry | B21: 50 | C21: 00h 03m
... A27: Train RandomForestClassifier | B27: 800 | C27: 00h 08m
A30: Frequency and probabilities
A32: Start event | B32: Frequency
A33: Build / Retrain Trigger | B33: On Mon-Fri; overall 20 times
A35: Gateway | B35: Decision | C35: Probability
A36: Meets deployment threshold? | B36: No (retune) | C36: 0.5
B37: Yes | C37: 0.5
A38: Drift detected? | B38: No | C38: 0.5
B39: Yes | C39: 0.5
A40: Retire model? | B40: No | C40: 0.5
B41: Yes | C41: 0.5
A44: Resources
A46: Role | B46: Work schedules | C46: Costs/hour
A47: Data Engineering | B47: 1 employees; 40 hours per week | C47: 50
A48: MLOps / Deployment | B48: 1 employees; 40 hours per week | C48: 50
A49: Model Development | B49: 1 employees; 40 hours per week | C49: 50
A50: Monitoring & Retraining | B50: 1 employees; 40 hours per week | C50: 50
